<sdf version='1.6'>
  <world name='default'>
    <model name='ground_plane'>
      <static>1</static>
      <link name='link'>
        <collision name='collision'>
          <geometry>
            <plane>
              <normal>0 0 1</normal>
              <size>100 100</size>
            </plane>
          </geometry>
          <surface>
            <friction>
              <ode>
                <mu>100</mu>
                <mu2>50</mu2>
              </ode>
              <torsional>
                <ode/>
              </torsional>
            </friction>
            <contact>
              <ode/>
            </contact>
            <bounce/>
          </surface>
          <max_contacts>10</max_contacts>
        </collision>
        <visual name='visual'>
          <cast_shadows>0</cast_shadows>
          <geometry>
            <plane>
              <normal>0 0 1</normal>
              <size>100 100</size>
            </plane>
          </geometry>
          <material>
            <script>
              <uri>file://media/materials/scripts/gazebo.material</uri>
              <name>Gazebo/Grey</name>
            </script>
          </material>
        </visual>
        <self_collide>0</self_collide>
        <kinematic>0</kinematic>
        <gravity>1</gravity>
      </link>
    </model>
    <light name='sun' type='directional'>
      <cast_shadows>1</cast_shadows>
      <pose frame=''>0 0 10 0 -0 0</pose>
      <diffuse>0.8 0.8 0.8 1</diffuse>
      <specular>0.1 0.1 0.1 1</specular>
      <attenuation>
        <range>1000</range>
        <constant>0.9</constant>
        <linear>0.01</linear>
        <quadratic>0.001</quadratic>
      </attenuation>
      <direction>-0.5 0.5 -1</direction>
    </light>
    <plugin name='SetupWorld' filename='libgazebo_plugins.so'/>
    <gravity>0 0 -9.8</gravity>
    <magnetic_field>6e-06 2.3e-05 -4.2e-05</magnetic_field>
    <atmosphere type='adiabatic'/>
    <physics name='default_physics' default='0' type='ode'>
      <max_step_size>0.001</max_step_size>
      <real_time_factor>1</real_time_factor>
      <real_time_update_rate>1000</real_time_update_rate>
    </physics>
    <scene>
      <ambient>0.4 0.4 0.4 1</ambient>
      <background>0.7 0.7 0.7 1</background>
      <shadows>1</shadows>
    </scene>
    <spherical_coordinates>
      <surface_model>EARTH_WGS84</surface_model>
      <latitude_deg>0</latitude_deg>
      <longitude_deg>0</longitude_deg>
      <elevation>0</elevation>
      <heading_deg>0</heading_deg>
    </spherical_coordinates>
    <model name='Barrier_West'>
      <static>1</static>
      <link name='link'>
        <inertial>
          <mass>1</mass>
          <inertia>
            <ixx>0.083</ixx>
            <ixy>0</ixy>
            <ixz>0</ixz>
            <iyy>0</iyy>
            <iyz>0</iyz>
            <izz>0.083</izz>
          </inertia>
        </inertial>
        <collision name='collision'>
          <geometry>
            <box>
              <size>0.05 15 0.33</size>
            </box>
          </geometry>
          <surface>
            <friction>
              <ode>
                <mu>1</mu>
                <mu2>1</mu2>
                <slip1>0</slip1>
                <slip2>0</slip2>
              </ode>
              <torsional>
                <ode/>
              </torsional>
            </friction>
            <contact>
              <ode/>
            </contact>
            <bounce/>
          </surface>
          <max_contacts>10</max_contacts>
        </collision>
        <visual name='visual'>
          <geometry>
            <box>
              <size>0.05 15 0.33</size>
            </box>
          </geometry>
          <material>
            <ambient>255 131 0 1</ambient>
            <diffuse>255 131 0 1</diffuse>
            <specular>0.1 0.1 0.1 1</specular>
            <emissive>0 0 0 0</emissive>
          </material>
        </visual>
        <self_collide>0</self_collide>
        <kinematic>0</kinematic>
        <gravity>1</gravity>
      </link>
      <pose frame=''>-7.5 0 0 0 -0 0</pose>
    </model>
    <model name='Barrier_North'>
      <static>1</static>
      <link name='link'>
        <inertial>
          <mass>1</mass>
          <inertia>
            <ixx>0.083</ixx>
            <ixy>0</ixy>
            <ixz>0</ixz>
            <iyy>0</iyy>
            <iyz>0</iyz>
            <izz>0.083</izz>
          </inertia>
        </inertial>
        <collision name='collision'>
          <geometry>
            <box>
              <size>0.05 15 0.33</size>
            </box>
          </geometry>
          <surface>
            <friction>
              <ode>
                <mu>1</mu>
                <mu2>1</mu2>
                <slip1>0</slip1>
                <slip2>0</slip2>
              </ode>
              <torsional>
                <ode/>
              </torsional>
            </friction>
            <contact>
              <ode/>
            </contact>
            <bounce/>
          </surface>
          <max_contacts>10</max_contacts>
        </collision>
        <visual name='visual'>
          <geometry>
            <box>
              <size>0.05 15 0.33</size>
            </box>
          </geometry>
          <material>
            <ambient>255 131 0 1</ambient>
            <diffuse>255 131 0 1</diffuse>
            <specular>0.1 0.1 0.1 1</specular>
            <emissive>0 0 0 0</emissive>
          </material>
        </visual>
        <self_collide>0</self_collide>
        <kinematic>0</kinematic>
        <gravity>1</gravity>
      </link>
      <pose frame=''>0 -7.5 0 0 -0 1.5708</pose>
    </model>
    <model name='Barrier_East'>
      <static>1</static>
      <link name='link'>
        <inertial>
          <mass>1</mass>
          <inertia>
            <ixx>0.083</ixx>
            <ixy>0</ixy>
            <ixz>0</ixz>
            <iyy>0</iyy>
            <iyz>0</iyz>
            <izz>0.083</izz>
          </inertia>
        </inertial>
        <collision name='collision'>
          <geometry>
            <box>
              <size>0.05 15 0.33</size>
            </box>
          </geometry>
          <surface>
            <friction>
              <ode>
                <mu>1</mu>
                <mu2>1</mu2>
                <slip1>0</slip1>
                <slip2>0</slip2>
              </ode>
              <torsional>
                <ode/>
              </torsional>
            </friction>
            <contact>
              <ode/>
            </contact>
            <bounce/>
          </surface>
          <max_contacts>10</max_contacts>
        </collision>
        <visual name='visual'>
          <geometry>
            <box>
              <size>0.05 15 0.33</size>
            </box>
          </geometry>
          <material>
            <ambient>255 131 0 1</ambient>
            <diffuse>255 131 0 1</diffuse>
            <specular>0.1 0.1 0.1 1</specular>
            <emissive>0 0 0 0</emissive>
          </material>
        </visual>
        <self_collide>0</self_collide>
        <kinematic>0</kinematic>
        <gravity>1</gravity>
      </link>
      <pose frame=''>7.5 0 0 0 -0 0</pose>
    </model>
    <model name='Barrier_South'>
      <static>1</static>
      <link name='link'>
        <inertial>
          <mass>1</mass>
          <inertia>
            <ixx>0.083</ixx>
            <ixy>0</ixy>
            <ixz>0</ixz>
            <iyy>0</iyy>
            <iyz>0</iyz>
            <izz>0.083</izz>
          </inertia>
        </inertial>
        <collision name='collision'>
          <geometry>
            <box>
              <size>0.05 15 0.33</size>
            </box>
          </geometry>
          <surface>
            <friction>
              <ode>
                <mu>1</mu>
                <mu2>1</mu2>
                <slip1>0</slip1>
                <slip2>0</slip2>
              </ode>
              <torsional>
                <ode/>
              </torsional>
            </friction>
            <contact>
              <ode/>
            </contact>
            <bounce/>
          </surface>
          <max_contacts>10</max_contacts>
        </collision>
        <visual name='visual'>
          <geometry>
            <box>
              <size>0.05 15 0.33</size>
            </box>
          </geometry>
          <material>
            <ambient>255 131 0 1</ambient>
            <diffuse>255 131 0 1</diffuse>
            <specular>0.1 0.1 0.1 1</specular>
            <emissive>0 0 0 0</emissive>
          </material>
        </visual>
        <self_collide>0</self_collide>
        <kinematic>0</kinematic>
        <gravity>1</gravity>
      </link>
      <pose frame=''>0 7.5 0 0 -0 1.5708</pose>
    </model>
    <model name='concrete_ground_plane'>
      <static>1</static>
      <link name='link'>
        <collision name='collision'>
          <geometry>
            <plane>
              <normal>0 0 1</normal>
              <size>100 100</size>
            </plane>
          </geometry>
          <surface>
            <friction>
              <ode>
                <mu>100</mu>
                <mu2>50</mu2>
              </ode>
              <torsional>
                <ode/>
              </torsional>
            </friction>
            <contact>
              <ode/>
            </contact>
            <bounce/>
          </surface>
          <max_contacts>10</max_contacts>
        </collision>
        <visual name='visual'>
          <cast_shadows>0</cast_shadows>
          <geometry>
            <plane>
              <normal>0 0 1</normal>
              <size>100 100</size>
            </plane>
          </geometry>
          <material>
            <script>
              <uri>model://media/materials/scripts</uri>
              <uri>model://media/materials/textures</uri>
              <name>ConcreteGroundPlane/Image</name>
            </script>
          </material>
        </visual>
        <self_collide>0</self_collide>
        <kinematic>0</kinematic>
        <gravity>1</gravity>
      </link>
      <pose frame=''>0 0 0 0 -0 0</pose>
    </model>
    <model name='collection_disk'>
      <static>1</static>
      <link name='link'>
        <visual name='visual'>
          <geometry>
            <box>
              <size>1.016 1.016 0.001</size>
            </box>
          </geometry>
          <material>
            <script>
              <uri>model://collection_disk/materials/scripts</uri>
              <uri>model://collection_disk/materials/textures</uri>
              <name>collection_disk/Diffuse</name>
            </script>
          </material>
        </visual>
        <self_collide>0</self_collide>
        <kinematic>0</kinematic>
        <gravity>1</gravity>
      </link>
      <plugin name='score_sim' filename='libgazebo_plugins_score.so'>
        <scoreTopic>/collectionZone/score</scoreTopic>
        <collectionZoneSquareSize>1.016</collectionZoneSquareSize>
        <updateRate>0.2</updateRate>
        <robotNamespace>/</robotNamespace>
      </plugin>
      <pose frame=''>0 0 0 0 -0 0</pose>
    </model>
    <model name='achilles'>
      <static>0</static>
      <link name='base_link'>
        <inertial>
          <mass>3</mass>
          <inertia>
            <ixx>0.006</ixx>
            <ixy>0</ixy>
            <ixz>0</ixz>
            <iyy>0.006</iyy>
            <iyz>0</iyz>
            <izz>0.006</izz>
          </inertia>
        </inertial>
        <collision name='base_link_collision'>
          <pose frame=''>0 0 0.03 0 -0 0</pose>
          <geometry>
            <box>
              <size>0.26 0.205 0.18</size>
            </box>
          </geometry>
          <max_contacts>10</max_contacts>
          <surface>
            <contact>
              <ode/>
            </contact>
            <bounce/>
            <friction>
              <torsional>
                <ode/>
              </torsional>
              <ode/>
            </friction>
          </surface>
        </collision>
        <visual name='base_link_visual'>
          <pose frame=''>0 0 -0.06 0 -0 0</pose>
          <geometry>
            <mesh>
              <uri>model://swarmie/meshes/Body.stl</uri>
              <scale>1 1 1</scale>
            </mesh>
          </geometry>
          <material>
            <script>
              <name>Gazebo/Grey</name>
              <uri>__default__</uri>
            </script>
          </material>
        </visual>
        <sensor name='us_left_sensor' type='ray'>
          <pose frame=''>0.15 0.07 0.053 0 -0 0.43633</pose>
          <visualize>0</visualize>
          <update_rate>5</update_rate>
          <ray>
            <scan>
              <horizontal>
                <samples>3</samples>
                <resolution>1</resolution>
                <min_angle>-0.478</min_angle>
                <max_angle>0.478</max_angle>
              </horizontal>
              <vertical>
                <samples>1</samples>
                <min_angle>0</min_angle>
                <max_angle>0</max_angle>
              </vertical>
            </scan>
            <range>
              <min>0.01</min>
              <max>3</max>
              <resolution>0.01</resolution>
            </range>
          </ray>
          <plugin name='us' filename='libhector_gazebo_ros_sonar.so'>
            <gaussianNoise>0.005</gaussianNoise>
            <topicName>/achilles/sonarLeft</topicName>
            <frameId>us_center_link</frameId>
            <robotNamespace>/</robotNamespace>
          </plugin>
        </sensor>
        <sensor name='us_right_sensor' type='ray'>
          <pose frame=''>0.15 -0.07 0.053 0 0 -0.43633</pose>
          <visualize>0</visualize>
          <update_rate>5</update_rate>
          <ray>
            <scan>
              <horizontal>
                <samples>3</samples>
                <resolution>1</resolution>
                <min_angle>-0.478</min_angle>
                <max_angle>0.478</max_angle>
              </horizontal>
              <vertical>
                <samples>1</samples>
                <min_angle>0</min_angle>
                <max_angle>0</max_angle>
              </vertical>
            </scan>
            <range>
              <min>0.01</min>
              <max>3</max>
              <resolution>0.01</resolution>
            </range>
          </ray>
          <plugin name='us' filename='libhector_gazebo_ros_sonar.so'>
            <gaussianNoise>0.005</gaussianNoise>
            <topicName>/achilles/sonarRight</topicName>
            <frameId>us_center_link</frameId>
            <robotNamespace>/</robotNamespace>
          </plugin>
        </sensor>
        <sensor name='us_center_sensor' type='ray'>
          <pose frame=''>0.15 0 0.053 0 -0 0</pose>
          <visualize>0</visualize>
          <update_rate>5</update_rate>
          <ray>
            <scan>
              <horizontal>
                <samples>3</samples>
                <resolution>1</resolution>
                <min_angle>-0.478</min_angle>
                <max_angle>0.478</max_angle>
              </horizontal>
              <vertical>
                <samples>1</samples>
                <min_angle>0</min_angle>
                <max_angle>0</max_angle>
              </vertical>
            </scan>
            <range>
              <min>0.01</min>
              <max>3</max>
              <resolution>0.01</resolution>
            </range>
          </ray>
          <plugin name='us' filename='libhector_gazebo_ros_sonar.so'>
            <gaussianNoise>0.005</gaussianNoise>
            <topicName>/achilles/sonarCenter</topicName>
            <frameId>us_center_link</frameId>
            <robotNamespace>/</robotNamespace>
          </plugin>
        </sensor>
        <sensor name='camera' type='camera'>
          <pose frame=''>0.145 -0.0162 0.088 0 0.628 0</pose>
          <visualize>0</visualize>
          <update_rate>6</update_rate>
          <camera name='head'>
            <horizontal_fov>1.0123</horizontal_fov>
            <image>
              <width>320</width>
              <height>240</height>
              <format>B8G8R8</format>
            </image>
            <clip>
              <near>0.02</near>
              <far>300</far>
            </clip>
            <noise>
              <type>gaussian</type>
              <mean>0</mean>
              <stddev>0.007</stddev>
            </noise>
          </camera>
          <plugin name='camera_controller' filename='libgazebo_ros_camera.so'>
            <alwaysOn>true</alwaysOn>
            <updateRate>0.0</updateRate>
            <cameraName>/achilles/camera</cameraName>
            <imageTopicName>/achilles/camera/image</imageTopicName>
            <cameraInfoTopicName>/achilles/camera/info</cameraInfoTopicName>
            <frameName>camera_link</frameName>
            <hackBaseline>0.1</hackBaseline>
            <distortionK1>0.0</distortionK1>
            <distortionK2>0.0</distortionK2>
            <distortionK3>0.0</distortionK3>
            <distortionT1>0.0</distortionT1>
            <distortionT2>0.0</distortionT2>
            <CxPrime>0.0</CxPrime>
            <Cx>0.0</Cx>
            <Cy>0.0</Cy>
            <focalLength>0.0</focalLength>
            <robotNamespace>/</robotNamespace>
          </plugin>
        </sensor>
        <collision name='top_plate_collision'>
          <pose frame=''>0 0 0.12 0 -0 0</pose>
          <geometry>
            <box>
              <size>0.25 0.3 0.005</size>
            </box>
          </geometry>
          <max_contacts>10</max_contacts>
          <surface>
            <contact>
              <ode/>
            </contact>
            <bounce/>
            <friction>
              <torsional>
                <ode/>
              </torsional>
              <ode/>
            </friction>
          </surface>
        </collision>
        <visual name='top_plate_visual'>
          <pose frame=''>0.0006 0 0.12 0 -0 0</pose>
          <geometry>
            <mesh>
              <uri>model://swarmie/meshes/CoverPlate.stl</uri>
              <scale>1 1 1</scale>
            </mesh>
          </geometry>
          <material>
            <script>
              <name>Gazebo/FlatBlack</name>
              <uri>__default__</uri>
            </script>
          </material>
        </visual>
        <collision name='cow_catcher_front_left_collision'>
          <pose frame=''>0.1675 0.06 -0.05 0 -0.4 0.3</pose>
          <geometry>
            <box>
              <size>0.01 0.08 0.06</size>
            </box>
          </geometry>
          <max_contacts>10</max_contacts>
          <surface>
            <contact>
              <ode/>
            </contact>
            <bounce/>
            <friction>
              <torsional>
                <ode/>
              </torsional>
              <ode/>
            </friction>
          </surface>
        </collision>
        <collision name='wheel_guard_front_left_collision'>
          <pose frame=''>0.148 0.13 -0.05 0 -0 0</pose>
          <geometry>
            <box>
              <size>0.01 0.08 0.06</size>
            </box>
          </geometry>
          <max_contacts>10</max_contacts>
          <surface>
            <contact>
              <ode/>
            </contact>
            <bounce/>
            <friction>
              <torsional>
                <ode/>
              </torsional>
              <ode/>
            </friction>
          </surface>
        </collision>
        <collision name='cow_catcher_front_right_collision'>
          <pose frame=''>0.1675 -0.06 -0.05 0 -0.4 -0.3</pose>
          <geometry>
            <box>
              <size>0.01 0.08 0.06</size>
            </box>
          </geometry>
          <max_contacts>10</max_contacts>
          <surface>
            <contact>
              <ode/>
            </contact>
            <bounce/>
            <friction>
              <torsional>
                <ode/>
              </torsional>
              <ode/>
            </friction>
          </surface>
        </collision>
        <collision name='wheel_guard_front_right_collision'>
          <pose frame=''>0.148 -0.13 -0.05 0 -0 0</pose>
          <geometry>
            <box>
              <size>0.01 0.08 0.06</size>
            </box>
          </geometry>
          <max_contacts>10</max_contacts>
          <surface>
            <contact>
              <ode/>
            </contact>
            <bounce/>
            <friction>
              <torsional>
                <ode/>
              </torsional>
              <ode/>
            </friction>
          </surface>
        </collision>
        <visual name='cow_catcher_front_visual'>
          <pose frame=''>0.1675 0 -0.08 1.57079 -0 0</pose>
          <geometry>
            <mesh>
              <uri>model://swarmie/meshes/CowCatcherFront.stl</uri>
              <scale>1 1 1</scale>
            </mesh>
          </geometry>
          <material>
            <script>
              <name>Gazebo/FlatBlack</name>
              <uri>__default__</uri>
            </script>
          </material>
        </visual>
        <collision name='cow_catcher_back_lower_collision'>
          <pose frame=''>-0.1305 0 -0.0665 1.57079 1.05 0</pose>
          <geometry>
            <box>
              <size>0.01 0.03 0.18</size>
            </box>
          </geometry>
          <max_contacts>10</max_contacts>
          <surface>
            <contact>
              <ode/>
            </contact>
            <bounce/>
            <friction>
              <torsional>
                <ode/>
              </torsional>
              <ode/>
            </friction>
          </surface>
        </collision>
        <visual name='cow_catcher_back_visual'>
          <pose frame=''>-0.1275 -0.1 -0.04 1.57079 0 3.1415</pose>
          <geometry>
            <mesh>
              <uri>model://swarmie/meshes/CowCatcherRear.stl</uri>
              <scale>1 1 1</scale>
            </mesh>
          </geometry>
          <material>
            <script>
              <name>Gazebo/FlatBlack</name>
              <uri>__default__</uri>
            </script>
          </material>
        </visual>
        <self_collide>0</self_collide>
        <kinematic>0</kinematic>
        <gravity>1</gravity>
      </link>
      <link name='gripper_wrist'>
        <pose frame=''>0.155 0 -0.013 0 -0 0</pose>
        <inertial>
          <mass>0.03</mass>
          <inertia>
            <ixx>0.00245</ixx>
            <ixy>0</ixy>
            <ixz>0</ixz>
            <iyy>0.00185</iyy>
            <iyz>0</iyz>
            <izz>0.00185</izz>
          </inertia>
        </inertial>
        <visual name='visual'>
          <pose frame=''>0 0 0 0 -0 0</pose>
          <geometry>
            <mesh>
              <uri>model://swarmie/meshes/GripperWrist.stl</uri>
              <scale>1 1 1</scale>
            </mesh>
          </geometry>
          <material>
            <script>
              <name>Gazebo/Grey</name>
              <uri>__default__</uri>
            </script>
          </material>
        </visual>
        <collision name='collision'>
          <pose frame=''>0 0 -0.0055 0 -0 0</pose>
          <geometry>
            <box>
              <size>0.07 0.05 0.07</size>
            </box>
          </geometry>
          <max_contacts>10</max_contacts>
          <surface>
            <contact>
              <ode/>
            </contact>
            <bounce/>
            <friction>
              <torsional>
                <ode/>
              </torsional>
              <ode/>
            </friction>
          </surface>
        </collision>
        <self_collide>0</self_collide>
        <kinematic>0</kinematic>
        <gravity>1</gravity>
      </link>
      <joint name='gripper_wrist_joint' type='revolute'>
        <parent>base_link</parent>
        <child>gripper_wrist</child>
        <pose frame=''>-0.0227 0 -0.0105 0 -0 0</pose>
        <axis>
          <xyz>0 1 0</xyz>
          <limit>
            <upper>0.7</upper>
            <lower>0</lower>
          </limit>
          <dynamics>
            <damping>0.5</damping>
            <spring_reference>0</spring_reference>
            <spring_stiffness>0</spring_stiffness>
          </dynamics>
          <use_parent_model_frame>1</use_parent_model_frame>
        </axis>
      </joint>
      <link name='gripper_left_finger'>
        <pose frame=''>0.214 0.016 0.0095 0 -0 0</pose>
        <inertial>
          <mass>0.005</mass>
          <inertia>
            <ixx>8.33e-05</ixx>
            <ixy>0</ixy>
            <ixz>0</ixz>
            <iyy>0.0005417</iyy>
            <iyz>0</iyz>
            <izz>0.0006083</izz>
          </inertia>
        </inertial>
        <collision name='collision'>
          <pose frame=''>0 0 0 0 0 -0.38</pose>
          <geometry>
            <box>
              <size>0.06 0.01 0.007</size>
            </box>
          </geometry>
          <surface>
            <friction>
              <ode>
                <mu>0.8</mu>
                <mu2>0.7</mu2>
              </ode>
              <torsional>
                <ode/>
              </torsional>
            </friction>
            <contact>
              <ode/>
            </contact>
            <bounce/>
          </surface>
          <max_contacts>10</max_contacts>
        </collision>
        <collision name='collision2'>
          <pose frame=''>0.033 -0.014 0 0 0 -0.38</pose>
          <geometry>
            <box>
              <size>0.01 0.01 0.007</size>
            </box>
          </geometry>
          <surface>
            <friction>
              <ode>
                <mu>0.8</mu>
                <mu2>0.7</mu2>
              </ode>
              <torsional>
                <ode/>
              </torsional>
            </friction>
            <contact>
              <ode/>
            </contact>
            <bounce/>
          </surface>
          <max_contacts>10</max_contacts>
        </collision>
        <visual name='visual'>
          <pose frame=''>0 0 0 0 -0 0</pose>
          <geometry>
            <mesh>
              <uri>model://swarmie/meshes/GripperFingerLeft.stl</uri>
              <scale>1 1 1</scale>
            </mesh>
          </geometry>
          <material>
            <script>
              <name>Gazebo/Grey</name>
              <uri>__default__</uri>
            </script>
          </material>
        </visual>
        <sensor name='finger' type='contact'>
          <contact>
            <collision>collision</collision>
            <topic>__default_topic__</topic>
          </contact>
        </sensor>
        <self_collide>0</self_collide>
        <kinematic>0</kinematic>
        <gravity>1</gravity>
      </link>
      <joint name='gripper_left_finger_joint' type='revolute'>
        <parent>gripper_wrist</parent>
        <child>gripper_left_finger</child>
        <pose frame=''>-0.0324 0.0052 0 0 -0 0</pose>
        <axis>
          <xyz>0 0 1</xyz>
          <limit>
            <upper>0.7854</upper>
            <lower>0</lower>
          </limit>
          <dynamics>
            <damping>0.3</damping>
            <spring_reference>0</spring_reference>
            <spring_stiffness>0</spring_stiffness>
          </dynamics>
          <use_parent_model_frame>1</use_parent_model_frame>
        </axis>
      </joint>
      <link name='gripper_right_finger'>
        <pose frame=''>0.214 -0.016 0.0095 0 -0 0</pose>
        <inertial>
          <mass>0.005</mass>
          <inertia>
            <ixx>8.33e-05</ixx>
            <ixy>0</ixy>
            <ixz>0</ixz>
            <iyy>0.0005417</iyy>
            <iyz>0</iyz>
            <izz>0.0006083</izz>
          </inertia>
        </inertial>
        <collision name='collision'>
          <pose frame=''>0 0 0 0 -0 0.38</pose>
          <geometry>
            <box>
              <size>0.06 0.01 0.007</size>
            </box>
          </geometry>
          <surface>
            <friction>
              <ode>
                <mu>0.8</mu>
                <mu2>0.7</mu2>
              </ode>
              <torsional>
                <ode/>
              </torsional>
            </friction>
            <contact>
              <ode/>
            </contact>
            <bounce/>
          </surface>
          <max_contacts>10</max_contacts>
        </collision>
        <collision name='collision2'>
          <pose frame=''>0.033 0.014 0 0 -0 0.38</pose>
          <geometry>
            <box>
              <size>0.01 0.01 0.007</size>
            </box>
          </geometry>
          <surface>
            <friction>
              <ode>
                <mu>0.8</mu>
                <mu2>0.7</mu2>
              </ode>
              <torsional>
                <ode/>
              </torsional>
            </friction>
            <contact>
              <ode/>
            </contact>
            <bounce/>
          </surface>
          <max_contacts>10</max_contacts>
        </collision>
        <visual name='visual'>
          <pose frame=''>0 0 0 0 -0 0</pose>
          <geometry>
            <mesh>
              <uri>model://swarmie/meshes/GripperFingerRight.stl</uri>
              <scale>1 1 1</scale>
            </mesh>
          </geometry>
          <material>
            <script>
              <name>Gazebo/Grey</name>
              <uri>__default__</uri>
            </script>
          </material>
        </visual>
        <sensor name='finger' type='contact'>
          <contact>
            <collision>collision</collision>
            <topic>__default_topic__</topic>
          </contact>
        </sensor>
        <self_collide>0</self_collide>
        <kinematic>0</kinematic>
        <gravity>1</gravity>
      </link>
      <joint name='gripper_right_finger_joint' type='revolute'>
        <parent>gripper_wrist</parent>
        <child>gripper_right_finger</child>
        <pose frame=''>-0.0324 -0.0052 0 0 -0 0</pose>
        <axis>
          <xyz>0 0 1</xyz>
          <limit>
            <upper>0</upper>
            <lower>-0.7854</lower>
          </limit>
          <dynamics>
            <damping>0.3</damping>
            <spring_reference>0</spring_reference>
            <spring_stiffness>0</spring_stiffness>
          </dynamics>
          <use_parent_model_frame>1</use_parent_model_frame>
        </axis>
      </joint>
      <link name='left_front_wheel'>
        <pose frame=''>0.095 0.135 -0.03 0 -0 0</pose>
        <inertial>
          <mass>1</mass>
          <inertia>
            <ixx>0.000776</ixx>
            <ixy>0</ixy>
            <ixz>0</ixz>
            <iyy>0.0012</iyy>
            <iyz>0</iyz>
            <izz>0.000776</izz>
          </inertia>
        </inertial>
        <collision name='collision'>
          <pose frame=''>0 0 0 1.5708 -0 0</pose>
          <geometry>
            <cylinder>
              <radius>0.0575</radius>
              <length>0.07</length>
            </cylinder>
          </geometry>
          <surface>
            <friction>
              <ode>
                <mu>0.8</mu>
                <mu2>0.7</mu2>
              </ode>
              <torsional>
                <ode/>
              </torsional>
            </friction>
            <contact>
              <ode/>
            </contact>
            <bounce/>
          </surface>
          <max_contacts>10</max_contacts>
        </collision>
        <visual name='visual'>
          <geometry>
            <mesh>
              <uri>model://swarmie/meshes/TireWheelLeft.stl</uri>
              <scale>1 1 1</scale>
            </mesh>
          </geometry>
          <material>
            <script>
              <name>Gazebo/Grey</name>
              <uri>__default__</uri>
            </script>
          </material>
        </visual>
        <self_collide>0</self_collide>
        <kinematic>0</kinematic>
        <gravity>1</gravity>
      </link>
      <joint name='left_front' type='revolute'>
        <parent>base_link</parent>
        <child>left_front_wheel</child>
        <axis>
          <xyz>0 1 0</xyz>
          <use_parent_model_frame>1</use_parent_model_frame>
          <limit>
            <lower>-1e+16</lower>
            <upper>1e+16</upper>
          </limit>
          <dynamics>
            <spring_reference>0</spring_reference>
            <spring_stiffness>0</spring_stiffness>
          </dynamics>
        </axis>
      </joint>
      <link name='right_front_wheel'>
        <pose frame=''>0.095 -0.135 -0.03 0 -0 0</pose>
        <inertial>
          <mass>1</mass>
          <inertia>
            <ixx>0.000776</ixx>
            <ixy>0</ixy>
            <ixz>0</ixz>
            <iyy>0.0012</iyy>
            <iyz>0</iyz>
            <izz>0.000776</izz>
          </inertia>
        </inertial>
        <collision name='collision'>
          <pose frame=''>0 0 0 -1.5708 0 0</pose>
          <geometry>
            <cylinder>
              <radius>0.0575</radius>
              <length>0.07</length>
            </cylinder>
          </geometry>
          <surface>
            <friction>
              <ode>
                <mu>0.8</mu>
                <mu2>0.7</mu2>
              </ode>
              <torsional>
                <ode/>
              </torsional>
            </friction>
            <contact>
              <ode/>
            </contact>
            <bounce/>
          </surface>
          <max_contacts>10</max_contacts>
        </collision>
        <visual name='visual'>
          <geometry>
            <mesh>
              <uri>model://swarmie/meshes/TireWheelRight.stl</uri>
              <scale>1 1 1</scale>
            </mesh>
          </geometry>
          <material>
            <script>
              <name>Gazebo/Grey</name>
              <uri>__default__</uri>
            </script>
          </material>
        </visual>
        <self_collide>0</self_collide>
        <kinematic>0</kinematic>
        <gravity>1</gravity>
      </link>
      <joint name='right_front' type='revolute'>
        <parent>base_link</parent>
        <child>right_front_wheel</child>
        <axis>
          <xyz>0 1 0</xyz>
          <use_parent_model_frame>1</use_parent_model_frame>
          <limit>
            <lower>-1e+16</lower>
            <upper>1e+16</upper>
          </limit>
          <dynamics>
            <spring_reference>0</spring_reference>
            <spring_stiffness>0</spring_stiffness>
          </dynamics>
        </axis>
      </joint>
      <link name='left_rear_wheel'>
        <pose frame=''>-0.095 0.135 -0.03 0 -0 0</pose>
        <inertial>
          <mass>1</mass>
          <inertia>
            <ixx>0.000776</ixx>
            <ixy>0</ixy>
            <ixz>0</ixz>
            <iyy>0.0012</iyy>
            <iyz>0</iyz>
            <izz>0.000776</izz>
          </inertia>
        </inertial>
        <collision name='collision'>
          <pose frame=''>0 0 0 1.5708 -0 0</pose>
          <geometry>
            <cylinder>
              <radius>0.0575</radius>
              <length>0.065</length>
            </cylinder>
          </geometry>
          <surface>
            <friction>
              <ode>
                <mu>0.8</mu>
                <mu2>0.7</mu2>
              </ode>
              <torsional>
                <ode/>
              </torsional>
            </friction>
            <contact>
              <ode/>
            </contact>
            <bounce/>
          </surface>
          <max_contacts>10</max_contacts>
        </collision>
        <visual name='visual'>
          <geometry>
            <mesh>
              <uri>model://swarmie/meshes/TireWheelLeft.stl</uri>
              <scale>1 1 1</scale>
            </mesh>
          </geometry>
          <material>
            <script>
              <name>Gazebo/Grey</name>
              <uri>__default__</uri>
            </script>
          </material>
        </visual>
        <self_collide>0</self_collide>
        <kinematic>0</kinematic>
        <gravity>1</gravity>
      </link>
      <joint name='left_rear' type='revolute'>
        <parent>base_link</parent>
        <child>left_rear_wheel</child>
        <axis>
          <xyz>0 1 0</xyz>
          <use_parent_model_frame>1</use_parent_model_frame>
          <limit>
            <lower>-1e+16</lower>
            <upper>1e+16</upper>
          </limit>
          <dynamics>
            <spring_reference>0</spring_reference>
            <spring_stiffness>0</spring_stiffness>
          </dynamics>
        </axis>
      </joint>
      <link name='right_rear_wheel'>
        <pose frame=''>-0.095 -0.135 -0.03 0 -0 0</pose>
        <inertial>
          <mass>1</mass>
          <inertia>
            <ixx>0.000776</ixx>
            <ixy>0</ixy>
            <ixz>0</ixz>
            <iyy>0.0012</iyy>
            <iyz>0</iyz>
            <izz>0.000776</izz>
          </inertia>
        </inertial>
        <collision name='collision'>
          <pose frame=''>0 0 0 -1.5708 0 0</pose>
          <geometry>
            <cylinder>
              <radius>0.0575</radius>
              <length>0.07</length>
            </cylinder>
          </geometry>
          <surface>
            <friction>
              <ode>
                <mu>0.8</mu>
                <mu2>0.7</mu2>
              </ode>
              <torsional>
                <ode/>
              </torsional>
            </friction>
            <contact>
              <ode/>
            </contact>
            <bounce/>
          </surface>
          <max_contacts>10</max_contacts>
        </collision>
        <visual name='visual'>
          <geometry>
            <mesh>
              <uri>model://swarmie/meshes/TireWheelRight.stl</uri>
              <scale>1 1 1</scale>
            </mesh>
          </geometry>
          <material>
            <script>
              <name>Gazebo/Grey</name>
              <uri>__default__</uri>
            </script>
          </material>
        </visual>
        <self_collide>0</self_collide>
        <kinematic>0</kinematic>
        <gravity>1</gravity>
      </link>
      <joint name='right_rear' type='revolute'>
        <parent>base_link</parent>
        <child>right_rear_wheel</child>
        <axis>
          <xyz>0 1 0</xyz>
          <use_parent_model_frame>1</use_parent_model_frame>
          <limit>
            <lower>-1e+16</lower>
            <upper>1e+16</upper>
          </limit>
          <dynamics>
            <spring_reference>0</spring_reference>
            <spring_stiffness>0</spring_stiffness>
          </dynamics>
        </axis>
      </joint>
      <plugin name='gripper_sim' filename='libgazebo_plugins_gripper.so'>
        <wristJoint>gripper_wrist_joint</wristJoint>
        <leftFingerJoint>gripper_left_finger_joint</leftFingerJoint>
        <rightFingerJoint>gripper_right_finger_joint</rightFingerJoint>
        <wristTopic>/achilles/wristAngle/cmd</wristTopic>
        <fingerTopic>/achilles/fingerAngle/cmd</fingerTopic>
        <debug>
          <printToConsole>false</printToConsole>
          <printDelayInSeconds>5.0</printDelayInSeconds>
        </debug>
        <updateRate>1000.0</updateRate>
        <wristPID>1.0 0.0 0.0</wristPID>
        <fingerPID>1.0 0.0 0.0</fingerPID>
        <wristForceLimits>-0.5 0.5</wristForceLimits>
        <fingerForceLimits>-0.5 0.5</fingerForceLimits>
        <robotNamespace>/</robotNamespace>
      </plugin>
      <plugin name='skid_steer_drive_controller' filename='libgazebo_ros_skid_steer_drive.so'>
        <updateRate>10</updateRate>
        <robotNamespace>/</robotNamespace>
        <leftFrontJoint>left_front</leftFrontJoint>
        <rightFrontJoint>right_front</rightFrontJoint>
        <leftRearJoint>left_rear</leftRearJoint>
        <rightRearJoint>right_rear</rightRearJoint>
        <wheelSeparation>0.27</wheelSeparation>
        <wheelDiameter>0.12</wheelDiameter>
        <robotBaseFrame>achilles/base_link</robotBaseFrame>
        <torque>2.8</torque>
        <commandTopic>/achilles/skidsteer</commandTopic>
        <odometryTopic>/achilles/odom</odometryTopic>
        <odometryFrame>achilles/odom</odometryFrame>
        <broadcastTF>0</broadcastTF>
      </plugin>
      <plugin name='gps_sim' filename='libhector_gazebo_ros_gps.so'>
        <alwaysOn>1</alwaysOn>
        <updateRate>5</updateRate>
        <bodyName>base_link</bodyName>
        <frameId>achilles/base_link</frameId>
        <topicName>/achilles/fix</topicName>
        <referenceLatitude>28.584810</referenceLatitude>
        <referenceLongitude>-80.649650</referenceLongitude>
        <referenceHeading>0.0</referenceHeading>
        <referenceAltitude>10.0</referenceAltitude>
        <offset>0.0 0.0 0.0</offset>
        <drift>0.1 0.1 0</drift>
        <driftFrequency>0.0 0.0 0.0</driftFrequency>
        <gaussianNoise>0.4 0.5 0.0</gaussianNoise>
        <robotNamespace>/</robotNamespace>
      </plugin>
      <plugin name='imu_sim' filename='libhector_gazebo_ros_imu.so'>
        <updateRate>10</updateRate>
        <bodyName>base_link</bodyName>
        <frameId>achilles/base_link</frameId>
        <topicName>/achilles/imu</topicName>
        <xyzOffset>0 0 0</xyzOffset>
        <rpyOffset>0 0 0</rpyOffset>
        <gaussianNoise>0</gaussianNoise>
        <accelDrift>0.5 0.5 0.5</accelDrift>
        <accelGaussianNoise>0.35 0.35 0.3</accelGaussianNoise>
        <rateDrift>0.1 0.1 0.1</rateDrift>
        <rateGaussianNoise>0.05 0.05 0.015</rateGaussianNoise>
        <headingDrift>0.01</headingDrift>
        <headingGaussianNoise>0.01</headingGaussianNoise>
        <robotNamespace>/</robotNamespace>
      </plugin>
      <pose frame=''>-1.308 0 0 0 -0 0</pose>
    </model>
    <model name='at0'>
      <static>0</static>
      <link name='link'>
        <inertial>
          <mass>0.01</mass>
          <inertia>
            <ixx>4e-05</ixx>
            <ixy>0</ixy>
            <ixz>0</ixz>
            <iyy>4e-05</iyy>
            <iyz>0</iyz>
            <izz>4e-05</izz>
          </inertia>
        </inertial>
        <visual name='visual'>
          <geometry>
            <box>
              <size>0.05 0.05 0.05</size>
            </box>
          </geometry>
          <material>
            <script>
              <uri>model://at0/materials/scripts</uri>
              <uri>model://at0/materials/textures</uri>
              <name>at0/Diffuse</name>
            </script>
          </material>
        </visual>
        <collision name='collision'>
          <geometry>
            <box>
              <size>0.05 0.05 0.05</size>
            </box>
          </geometry>
          <surface>
            <friction>
              <ode>
                <mu>0.8</mu>
                <mu2>0.7</mu2>
              </ode>
              <torsional>
                <ode/>
              </torsional>
            </friction>
            <contact>
              <ode/>
            </contact>
            <bounce/>
          </surface>
          <max_contacts>10</max_contacts>
        </collision>
        <self_collide>0</self_collide>
        <kinematic>0</kinematic>
        <gravity>1</gravity>
      </link>
      <pose frame=''>-1.2039 1.04643 0 0 -0 0</pose>
    </model>
    <state world_name='default'>
      <sim_time>576 975000000</sim_time>
      <real_time>39 154965682</real_time>
      <wall_time>1519255622 872234761</wall_time>
      <iterations>576975</iterations>
      <model name='Barrier_East'>
        <pose frame=''>7.5 0 0 0 -0 0</pose>
        <scale>1 1 1</scale>
        <link name='link'>
          <pose frame=''>7.5 0 0 0 -0 0</pose>
          <velocity>0 0 0 0 -0 0</velocity>
          <acceleration>0 0 0 0 -0 0</acceleration>
          <wrench>0 0 0 0 -0 0</wrench>
        </link>
      </model>
      <model name='Barrier_North'>
        <pose frame=''>0 -7.5 0 0 -0 1.5708</pose>
        <scale>1 1 1</scale>
        <link name='link'>
          <pose frame=''>0 -7.5 0 0 -0 1.5708</pose>
          <velocity>0 0 0 0 -0 0</velocity>
          <acceleration>0 0 0 0 -0 0</acceleration>
          <wrench>0 0 0 0 -0 0</wrench>
        </link>
      </model>
      <model name='Barrier_South'>
        <pose frame=''>0 7.5 0 0 -0 1.5708</pose>
        <scale>1 1 1</scale>
        <link name='link'>
          <pose frame=''>0 7.5 0 0 -0 1.5708</pose>
          <velocity>0 0 0 0 -0 0</velocity>
          <acceleration>0 0 0 0 -0 0</acceleration>
          <wrench>0 0 0 0 -0 0</wrench>
        </link>
      </model>
      <model name='Barrier_West'>
        <pose frame=''>-7.5 0 0 0 -0 0</pose>
        <scale>1 1 1</scale>
        <link name='link'>
          <pose frame=''>-7.5 0 0 0 -0 0</pose>
          <velocity>0 0 0 0 -0 0</velocity>
          <acceleration>0 0 0 0 -0 0</acceleration>
          <wrench>0 0 0 0 -0 0</wrench>
        </link>
      </model>
      <model name='achilles'>
        <pose frame=''>-1.32556 -0.003121 0.0875 0 4e-06 -0.004703</pose>
        <scale>1 1 1</scale>
        <link name='base_link'>
          <pose frame=''>-1.32556 -0.003121 0.0875 0 4e-06 -0.004703</pose>
          <velocity>-4.7e-05 -3.9e-05 9e-06 -0.000242 -0.000212 -7.1e-05</velocity>
          <acceleration>0.050077 -0.017981 -0.014408 0.289396 0.303649 0.016278</acceleration>
          <wrench>0.150232 -0.053944 -0.043225 0 -0 0</wrench>
        </link>
        <link name='gripper_left_finger'>
          <pose frame=''>-1.11375 0.036278 0.040333 0.536531 0.473718 0.911754</pose>
          <velocity>-3.9e-05 -3.9e-05 8.6e-05 0.00042 -0.000609 0.000709</velocity>
          <acceleration>0.01244 0.037241 -0.057056 0.601006 0.037124 2.41482</acceleration>
          <wrench>6.2e-05 0.000186 -0.000285 0 -0 0</wrench>
        </link>
        <link name='gripper_right_finger'>
          <pose frame=''>-1.11414 -0.044523 0.040339 -0.536746 0.473469 -0.92163</pose>
          <velocity>-3.3e-05 -7.4e-05 9.5e-05 -0.000413 -0.000684 -0.000336</velocity>
          <acceleration>0.014375 -0.033146 -0.081413 0.215132 0.515699 -2.66268</acceleration>
          <wrench>7.2e-05 -0.000166 -0.000407 0 -0 0</wrench>
        </link>
        <link name='gripper_wrist'>
          <pose frame=''>-1.16914 -0.003857 0.057407 0 0.700005 -0.004704</pose>
          <velocity>-3.8e-05 -5.8e-05 5.1e-05 -0.000239 -0.000618 -7.2e-05</velocity>
          <acceleration>0.04036 -0.006296 -0.06424 0.290796 0.405212 0.057263</acceleration>
          <wrench>0.001211 -0.000189 -0.001927 0 -0 0</wrench>
        </link>
        <link name='left_front_wheel'>
          <pose frame=''>-1.22993 0.13143 0.0575 -4e-06 0.106085 -0.004694</pose>
          <velocity>-1e-06 -2.9e-05 -1.4e-05 0.000512 0.000764 -0.001329</velocity>
          <acceleration>0.022613 -0.023747 -0.017216 0.419153 0.235256 0.261663</acceleration>
          <wrench>0.022613 -0.023747 -0.017216 0 -0 0</wrench>
        </link>
        <link name='left_rear_wheel'>
          <pose frame=''>-1.41993 0.132324 0.0575 -1.6e-05 -0.235715 -0.004694</pose>
          <velocity>1e-06 -3.2e-05 9e-06 0.000553 0.000416 -0.000744</velocity>
          <acceleration>0.029573 -0.006021 -0.026221 0.065642 0.390614 0.221356</acceleration>
          <wrench>0.029573 -0.006021 -0.026221 0 -0 0</wrench>
        </link>
        <link name='right_front_wheel'>
          <pose frame=''>-1.2312 -0.138567 0.0575 -5e-06 0.046529 -0.004705</pose>
          <velocity>-3.9e-05 -2.4e-05 1.4e-05 0.000421 -0.000552 -0.000183</velocity>
          <acceleration>0.03711 -0.015631 -0.045415 0.25934 0.531788 0.178652</acceleration>
          <wrench>0.03711 -0.015631 -0.045415 0 -0 0</wrench>
        </link>
        <link name='right_rear_wheel'>
          <pose frame=''>-1.4212 -0.137672 0.057501 4.5e-05 -0.348561 -0.004712</pose>
          <velocity>-7.2e-05 -3.1e-05 4e-06 0.000375 -0.001584 -0.000604</velocity>
          <acceleration>0.038914 0.000251 0.028598 -0.013295 0.606226 -0.109179</acceleration>
          <wrench>0.038914 0.000251 0.028598 0 -0 0</wrench>
        </link>
      </model>
      <model name='at0'>
        <pose frame=''>-1.2039 1.04643 0.02499 0 2e-06 0</pose>
        <scale>1 1 1</scale>
        <link name='link'>
          <pose frame=''>-1.2039 1.04643 0.02499 0 2e-06 0</pose>
          <velocity>0 0 0 0 -0 0</velocity>
          <acceleration>0 0 -9.8 0 -0 0</acceleration>
          <wrench>0 0 -0.098 0 -0 0</wrench>
        </link>
      </model>
      <model name='collection_disk'>
        <pose frame=''>0 0 0 0 -0 0</pose>
        <scale>1 1 1</scale>
        <link name='link'>
          <pose frame=''>0 0 0 0 -0 0</pose>
          <velocity>0 0 0 0 -0 0</velocity>
          <acceleration>0 0 0 0 -0 0</acceleration>
          <wrench>0 0 0 0 -0 0</wrench>
        </link>
      </model>
      <model name='concrete_ground_plane'>
        <pose frame=''>0 0 0 0 -0 0</pose>
        <scale>1 1 1</scale>
        <link name='link'>
          <pose frame=''>0 0 0 0 -0 0</pose>
          <velocity>0 0 0 0 -0 0</velocity>
          <acceleration>0 0 0 0 -0 0</acceleration>
          <wrench>0 0 0 0 -0 0</wrench>
        </link>
      </model>
      <model name='ground_plane'>
        <pose frame=''>0 0 0 0 -0 0</pose>
        <scale>1 1 1</scale>
        <link name='link'>
          <pose frame=''>0 0 0 0 -0 0</pose>
          <velocity>0 0 0 0 -0 0</velocity>
          <acceleration>0 0 0 0 -0 0</acceleration>
          <wrench>0 0 0 0 -0 0</wrench>
        </link>
      </model>
      <light name='sun'>
        <pose frame=''>0 0 10 0 -0 0</pose>
      </light>
    </state>
    <gui fullscreen='0'>
      <camera name='user_camera'>
        <pose frame=''>5 -5 2 0 0.275643 2.35619</pose>
        <view_controller>orbit</view_controller>
        <projection_type>perspective</projection_type>
      </camera>
    </gui>
  </world>
</sdf>
